Workbook

Sheet Historicals
B2: Historicals
B3: CAD (Thousands) | D3: 2019 | E3: =D3+1 -> 2020 | F3: =E3+1 -> 2021 | G3: =F3+1 -> 2022 | H3: =G3+1 -> 2023 | I3: =H3+1 -> 2024 | J3: =I3+1 -> 2025
A4: * | B4: Income Statement | K4: 6 Year CAGR
B5: Revenues | D5: 655129 | E5: 785086 | F5: 1281815 | G5: 1460806 | H5: 1395088 | I5: 1524294 | J5: 1606579 | K5: =_xlfn.RRI(6,D5,J5) -> 0.16125931
B6: Cost of Sales | D6: -351946 | E6: -399368 | F6: -428882 | G6: -458678 | H6: -822762 | I6: -884022 | J6: -1056243
B7: Gross Profit | D7: =SUM(D5:D6) -> 303183 | E7: =SUM(E5:E6) -> 385718 | F7: =SUM(F5:F6) -> 852933 | G7: =SUM(G5:G6) -> 1002128 | H7: =SUM(H5:H6) -> 572326 | I7: =SUM(I5:I6) -> 640272 | J7: =SUM(J5:J6) -> 550336
B8: SG&A Exp | D8: -28073 | E8: -37178 | F8: -43693 | G8: -67119 | H8: -79972 | I8: -87481 | J8: -81221
B9: EBITDA | D9: =SUM(D7:D8) -> 275110 | E9: =SUM(E7:E8) -> 348540 | F9: =SUM(F7:F8) -> 809240 | G9: =SUM(G7:G8) -> 935009 | H9: =SUM(H7:H8) -> 492354 | I9: =SUM(I7:I8) -> 552791 | J9: =SUM(J7:J8) -> 469115
B10: D&A | D10: -14551 | E10: -22001 | F10: -35177 | G10: -43929 | H10: -121044 | I10: -123584 | J10: -148604
B11: EBIT | D11: =SUM(D9:D10) -> 260559 | E11: =SUM(E9:E10) -> 326539 | F11: =SUM(F9:F10) -> 774063 | G11: =SUM(G9:G10) -> 891080 | H11: =SUM(H9:H10) -> 371310 | I11: =SUM(I9:I10) -> 429207 | J11: =SUM(J9:J10) -> 320511 | K11: =_xlfn.RRI(6,D11,J11) -> 0.035117085
B12: Interest Inc/(Exp) | D12: -50010 | E12: -84244 | F12: -22428 | G12: -11045 | H12: -25587 | I12: -36138 | J12: -57539
B13: Non-Operating Inc/(Exp) | D13: 0 | E13: -1107 | F13: 10237 | G13: 8560 | H13: 822 | I13: -242 | J13: 2175
B14: Unsual Items Inc/(Exp) | D14: 3062 | E14: 0 | F14: 0 | G14: -17752 | H14: 0 | I14: 0 | J14: 0
B15: EBT | D15: =SUM(D11:D14) -> 213611 | E15: =SUM(E11:E14) -> 241188 | F15: =SUM(F11:F14) -> 761872 | G15: =SUM(G11:G14) -> 870843 | H15: =SUM(H11:H14) -> 346545 | I15: =SUM(I11:I14) -> 392827 | J15: =SUM(J11:J14) -> 265147
B16: Tax | D16: -66012 | E16: -120138 | F16: -297447 | G16: -348258 | H16: -145838 | I16: -158636 | J16: -123102
B17: Net Income | D17: =SUM(D15:D16) -> 147599 | E17: =SUM(E15:E16) -> 121050 | F17: =SUM(F15:F16) -> 464425 | G17: =SUM(G15:G16) -> 522585 | H17: =SUM(H15:H16) -> 200707 | I17: =SUM(I15:I16) -> 234191 | J17: =SUM(J15:J16) -> 142045 | K17: =_xlfn.RRI(6,D17,J17) -> -0.0063721492
B19: No. of Shareholders | D19: 420700 | E19: 441600 | F19: 478600 | G19: 507600 | H19: 517000 | I19: 517600 | J19: 518200
B20: EPS | D20: =D17/D19 -> 0.35084145 | E20: =E17/E19 -> 0.27411685 | F20: =F17/F19 -> 0.97038237 | G20: =G17/G19 -> 1.0295213 | H20: =H17/H19 -> 0.3882147 | I20: =I17/I19 -> 0.45245556 | J20: =J17/J19 -> 0.27411231
A22: * | B22: Balance Sheet
B23: Cash and Cash Equivalents | D23: 135424 | E23: 281363 | F23: 609316 | G23: 321892 | H23: 326806 | I23: 400061 | J23: 117451
B24: Short-term Investments | D24: 17907 | E24: 17291 | F24: 27200 | G24: 30777 | H24: 312 | I24: 0 | J24: 0
B25: Receivables | D25: 93012 | E25: 31249 | F25: 98755 | G25: 124137 | H25: 162268 | I25: 120079 | J25: 202470
B26: Inventories | D26: 44154 | E26: 58611 | F26: 66814 | G26: 98861 | H26: 167670 | I26: 332611 | J26: 357489
B27: Other Current Assets | D27: 24186 | E27: 13035 | F27: 5454 | G27: 20272 | H27: 80963 | I27: 47368 | J27: 54895
B28: Total Current Assets | D28: =SUM(D23:D27) -> 314683 | E28: =SUM(E23:E27) -> 401549 | F28: =SUM(F23:F27) -> 807539 | G28: =SUM(G23:G27) -> 595939 | H28: =SUM(H23:H27) -> 738019 | I28: =SUM(I23:I27) -> 900119 | J28: =SUM(J23:J27) -> 732305
B30: Exploration and Evaluation Assets | D30: 81508 | E30: 75525 | F30: 76106 | G30: 107810 | H30: 117127 | I30: 131827 | J30: 148029
B31: Property, Plant and Equipment | D31: 224123 | E31: 365470 | F31: 504985 | G31: 1070030 | H31: 1261968 | I31: 1545961 | J31: 2046406
B32: Investments | D32: 2653 | E32: 1546 | F32: 9704 | G32: 14158 | H32: 14751 | I32: 14509 | J32: 15393
B33: Intangible Assets | D33: 1472 | E33: 6070 | F33: 6257 | G33: 8545 | H33: 7866 | I33: 5172 | J33: 5219 | K33: =SUM(J33,J35) -> 11761
B34: Restricted Cash | D34: 0 | E34: 0 | F34: 44012 | G34: 43736 | H34: 0 | I34: 0 | J34: 0
B35: Other Non-current Assets | D35: 10800 | E35: 0 | F35: 0 | G35: 0 | H35: 8595 | I35: 8589 | J35: 6542
B36: Advance Payments | D36: 38250 | E36: 32438 | F36: 48303 | G36: 149012 | H36: 166943 | I36: 83374 | J36: 76307
B37: Total Non-Current Assets | D37: =SUM(D30:D36) -> 358806 | E37: =SUM(E30:E36) -> 481049 | F37: =SUM(F30:F36) -> 689367 | G37: =SUM(G30:G36) -> 1393291 | H37: =SUM(H30:H36) -> 1577250 | I37: =SUM(I30:I36) -> 1789432 | J37: =SUM(J30:J36) -> 2297896
B38: Total Assets | D38: =SUM(D37,D28) -> 673489 | E38: =SUM(E37,E28) -> 882598 | F38: =SUM(F37,F28) -> 1496906 | G38: =SUM(G37,G28) -> 1989230 | H38: =SUM(H37,H28) -> 2315269 | I38: =SUM(I37,I28) -> 2689551 | J38: =SUM(J37,J28) -> 3030201
B40: Accounts Payable - Other | D40: 44697 | E40: 55158 | F40: 102225 | G40: 192151 | H40: 178578 | I40: 251778 | J40: 289660
B41: Current Portion of Long-term Debt | D41: 35852 | E41: 0 | F41: 0 | G41: 71995 | H41: 27080 | I41: 31061 | J41: 40725
B42: Income and Mining Taxes Payable | D42: 34059 | E42: 57761 | F42: 191542 | G42: 22744 | H42: 0 | I42: 40232 | J42: 25895
B43: Current Portion of Provisions | D43: 0 | E43: 0 | F43: 0 | G43: 0 | H43: 0 | I43: 0 | J43: 2402
B44: Total Current Liabilities | D44: =SUM(D40:D43) -> 114608 | E44: =SUM(E40:E43) -> 112919 | F44: =SUM(F40:F43) -> 293767 | G44: =SUM(G40:G43) -> 286890 | H44: =SUM(H40:H43) -> 205658 | I44: =SUM(I40:I43) -> 323071 | J44: =SUM(J40:J43) -> 358682
B46: Long-term Debt | D46: 193038 | E46: 275968 | F46: 214951 | G46: 251365 | H46: 448201 | I46: 508367 | J46: 666576
...

Sheet WCC
B2: WCC
B3: CAD (Thousands) | D3: 2019 | E3: =D3+1 -> 2020 | F3: =E3+1 -> 2021 | G3: =F3+1 -> 2022 | H3: =G3+1 -> 2023 | I3: =H3+1 -> 2024 | J3: =I3+1 -> 2025
B4: Operating Current Assets
B5: Short-term Investments | D5: 17907 | E5: 17291 | F5: 27200 | G5: 30777 | H5: 312 | I5: 0 | J5: 0
B6: Receivables | D6: 93012 | E6: 31249 | F6: 98755 | G6: 124137 | H6: 162268 | I6: 120079 | J6: 202470
B7: Inventories | D7: 44154 | E7: 58611 | F7: 66814 | G7: 98861 | H7: 167670 | I7: 332611 | J7: 357489
B8: Other Current Assets | D8: 24186 | E8: 13035 | F8: 5454 | G8: 20272 | H8: 80963 | I8: 47368 | J8: 54895
B9: Total Operating Current Assets | D9: =SUM(D5:D8) -> 179259 | E9: =SUM(E5:E8) -> 120186 | F9: =SUM(F5:F8) -> 198223 | G9: =SUM(G5:G8) -> 274047 | H9: =SUM(H5:H8) -> 411213 | I9: =SUM(I5:I8) -> 500058 | J9: =SUM(J5:J8) -> 614854
B11: Operating Current Liabilities
B12: Accounts Payable - Other | D12: 44697 | E12: 55158 | F12: 102225 | G12: 192151 | H12: 178578 | I12: 251778 | J12: 289660
B13: Current Portion of Long-term Debt | D13: 35852 | E13: 0 | F13: 0 | G13: 71995 | H13: 27080 | I13: 31061 | J13: 40725
B14: Income and Mining Taxes Payable | D14: 34059 | E14: 57761 | F14: 191542 | G14: 22744 | H14: 0 | I14: 40232 | J14: 25895
B15: =Historicals!B43 -> Current Portion of Provisions | C15: =Historicals!C43 -> 0 | D15: =Historicals!D43 -> 0 | E15: =Historicals!E43 -> 0 | F15: =Historicals!F43 -> 0 | G15: =Historicals!G43 -> 0 | H15: =Historicals!H43 -> 0 | I15: =Historicals!I43 -> 0 | J15: =Historicals!J43 -> 2402
B16: Total Operating Current Liabilities | D16: =SUM(D12:D14) -> 114608 | E16: =SUM(E12:E14) -> 112919 | F16: =SUM(F12:F14) -> 293767 | G16: =SUM(G12:G14) -> 286890 | H16: =SUM(H12:H14) -> 205658 | I16: =SUM(I12:I14) -> 323071 | J16: =SUM(J12:J15) -> 358682
B18: Net Working Capital | D18: =D9-D16 -> 64651 | E18: =E9-E16 -> 7267 | F18: =F9-F16 -> -95544 | G18: =G9-G16 -> -12843 | H18: =H9-H16 -> 205555 | I18: =I9-I16 -> 176987 | J18: =J9-J16 -> 256172
B19: Working Capital Changes | E19: =E18-D18 -> -57384 | F19: =F18-E18 -> -102811 | G19: =G18-F18 -> 82701 | H19: =H18-G18 -> 218398 | I19: =I18-H18 -> -28568 | J19: =J18-I18 -> 79185

Sheet WACC
A2: * | B2: WACC using Comparables Approach
B4: Peer Comps
B5: Name | D5: Country | E5: Total Debt | F5: Total Equity | G5: Tax Rate | H5: Debt/Equity | I5: Debt/Capital | J5: Levered Beta | K5: Unlevered Beta
B6: Fortescue Ltd (ASX:FMG) | D6: AUS | E6: 5439 | F6: 19956 | G6: 0.3255 | H6: =E6/F6 -> 0.27254961 | I6: =E6/SUM(E6:G6) -> 0.21417327 | J6: 0.98 | K6: =J6/(1+(1-G6)*H6) -> 0.82781827
B7: Labrador Iron Ore Royalty Corporation (TSX:LIF) | D7: CAD | E7: 0 | F7: 455.5 | G7: 0.2013 | H7: =E7/F7 -> 0 | I7: =E7/SUM(E7:G7) -> 0 | J7: 0.93 | K7: =J7/(1+(1-G7)*H7) -> 0.93
B8: Grange Resources Limited (ASX:GRR) | D8: AUD | E8: 0.9 | F8: 683.2 | G8: 0.2772 | H8: =E8/F8 -> 0.0013173302 | I8: =E8/SUM(E8:G8) -> 0.0013150643 | J8: 1.04 | K8: =J8/(1+(1-G8)*H8) -> 1.0390107
B9: Mount Gibson Iron Limited (ASX:MGX) | D9: AUD | E9: 3.4 | F9: 291.8 | G9: 0 | H9: =E9/F9 -> 0.011651816 | I9: =E9/SUM(E9:G9) -> 0.011517615 | J9: 0.84 | K9: =J9/(1+(1-G9)*H9) -> 0.8303252
B10: Shougang Hierro Peru S.a.a. (BVL:SHPC1) | D10: PER | E10: 30.7 | F10: 1118.1 | G10: 0.3055 | H10: =E10/F10 -> 0.027457294 | I10: =E10/SUM(E10:G10) -> 0.026716433 | J10: -0.63 | K10: =J10/(1+(1-G10)*H10) -> -0.61821127
B11: CAP S.A. (SNSE:CAP) | D11: CLP | E11: 1783.8 | F11: 3186 | G11: 0.6666 | H11: =E11/F11 -> 0.55988701 | I11: =E11/SUM(E11:G11) -> 0.35887979 | J11: 1.48 | K11: =J11/(1+(1-G11)*H11) -> 1.2471914
B12: Godawari Power & Ispat Limited (NSEI:GPIL) | D12: INR | E12: 34.5 | F12: 550.9 | G12: 0.2555 | H12: =E12/F12 -> 0.062624796 | I12: =E12/SUM(E12:G12) -> 0.058908351 | J12: 0.72 | K12: =J12/(1+(1-G12)*H12) -> 0.68792603
B13: HBIS Resources Co., Ltd. (SZSE:000923) | D13: CNY | E13: 0.2 | F13: 1791 | G13: 0.2012 | H13: =E13/F13 -> 0.00011166946 | I13: =E13/SUM(E13:G13) -> 0.00011164445 | J13: 1.12 | K13: =J13/(1+(1-G13)*H13) -> 1.1199001
B14: The Sandur Manganese & Iron Ores Limited (BSE:504918) | D14: INR | E14: 210.9 | F14: 293.2 | G14: 0.2411 | H14: =E14/F14 -> 0.71930423 | I14: =E14/SUM(E14:G14) -> 0.41816937 | J14: 0.86 | K14: =J14/(1+(1-G14)*H14) -> 0.55631744
B15: Cleveland-Cliffs Inc. (NYSE:CLF) | D15: USD | E15: 7801 | F15: 6897 | H15: =E15/F15 -> 1.1310715 | I15: =E15/SUM(E15:F15) -> 0.53075248 | J15: 1.98 | K15: =J15/(1+(1-G15)*H15) -> 0.92911008
B16: Kumba Iron Ore Limited (JSE:KIO) | D16: ZAR | E16: 126 | F16: 3974.8 | G16: 0.2767 | H16: =E16/F16 -> 0.031699708 | I16: =E16/SUM(E16:G16) -> 0.030723639 | J16: 1.07 | K16: =J16/(1+(1-G16)*H16) -> 1.0460165
B17: Ferrexpo plc (LSE:FXPO) | D17: GBP | E17: 5.1 | F17: 923.7 | H17: =E17/F17 -> 0.0055212731 | I17: =E17/SUM(E17:F17) -> 0.0054909561 | J17: 1.14 | K17: =J17/(1+(1-G17)*H17) -> 1.1337403
B19: Average | G19: =AVERAGE(G6:G17) -> 0.27506 | H19: =AVERAGE(H6:H17) -> 0.23526635 | I19: =AVERAGE(I6:I17) -> 0.13806322 | J19: =AVERAGE(J6:J17) -> 0.96083333 | K19: =AVERAGE(K6:K17) -> 0.81076206
B20: Median | G20: =MEDIAN(G6:G17) -> 0.2661 | H20: =MEDIAN(H6:H17) -> 0.029578501 | I20: =MEDIAN(I6:I17) -> 0.028720036 | J20: =MEDIAN(J6:J17) -> 1.01 | K20: =MEDIAN(K6:K17) -> 0.92955504
B23: Cost of Debt | G23: Cost of Equity
B25: Pre-Tax Cost of Debt | E25: =AVERAGE(Financing!H13:J13) -> 0.042219668 | G25: Risk Free Rate (CAD) | K25: 0.032
B26: Tax | E26: =-Historicals!J16/Historicals!J15 -> 0.46427831 | G26: Beta (AUD) | K26: =K36 -> 1.1976996
B27: Cost of Debt | E27: =E25*(1-E26) -> 0.022617992 | G27: Equity Risk Premium (AUD) | K27: ='Market Return'!G8-0.0445 -> 0.038227391
G28: Cost of Equity | K28: =K25+(K26*K27) -> 0.077784932
B31: Capital Structure | G31: Levered Beta
D33: Current | E33: Target | G33: Comps Median Unlevered Beta | K33: =K20 -> 0.92955504
B34: Total Debt | C34: =Historicals!J46+Historicals!J41 -> 707301 | D34: =C34/C36 -> 0.33009816 | E34: 0.35 | G34: Target Debt/Equity | K34: =E38 -> 0.53846154
B35: Total Equity | C35: =Historicals!J65 -> 1435398 | D35: =C35/C36 -> 0.66990184 | E35: =1-E34 -> 0.65 | G35: Tax Rate | K35: =E26 -> 0.46427831
B36: Total Capital | C36: =SUM(C34:C35) -> 2142699 | D36: =SUM(D34:D35) -> 1 | E36: =SUM(E34:E35) -> 1 | G36: Levered Beta | K36: =K33*(1+(1-K35)*K34) -> 1.1976996
B38: Debt/Equity | D38: =C34/C35 -> 0.49275602 | E38: =E34/E35 -> 0.53846154
G41: WACC
J43: Cost | K43: Weight
G44: Debt | J44: =E27 -> 0.022617992 | K44: =E34 -> 0.35
G45: Equity | J45: =K28 -> 0.077784932 | K45: =E35 -> 0.65
G46: WACC | J46: =J44*K44+(J45*K45) -> 0.058476503
A49: * | B49: WACC using Regression
B51: Cost of Debt | G51: Cost of Equity
B53: Pre-Tax Cost of Debt | E53: =E25 -> 0.042219668 | G53: Risk Free Rate | K53: =K25 -> 0.032
B54: Tax Rate | E54: =E26 -> 0.46427831 | G54: Equity Risk Premium | K54: =K27 -> 0.038227391
B55: Cost of Debt | E55: =E53*(1-E54) -> 0.022617992 | G55: Levered Beta | K55: =Beta!K12 -> 0.92940315
G56: Cost of Equity | K56: =K53+(K54*K55) -> 0.067528658
G59: WACC
...

Sheet Beta
B2: Beta - 5Y Monthly
B4: Champion Iron | F4: S&P/ASX 200 Index | J4: Beta Drifting
B6: Date | C6: Returns | D6: % Change | F6: Date | G6: Returns | H6: % Change | J6: Raw Levered Beta | K6: =SLOPE(D8:D67,H8:H67) -> 0.90587087
B7: 44165 | C7: 4.51 | F7: 44165 | G7: 6517.81 | J7: Raw Beta Weight | K7: 0.75
B8: 44196 | C8: 4.75 | D8: =C8/C7-1 -> 0.053215078 | F8: 44196 | G8: 6587.1 | H8: =G8/G7-1 -> 0.010630871
B9: 44227 | C9: 5.11 | D9: =C9/C8-1 -> 0.075789474 | F9: 44227 | G9: 6607.36 | H9: =G9/G8-1 -> 0.0030757086 | J9: Market Beta | K9: 1
B10: 44255 | C10: 5.43 | D10: =C10/C9-1 -> 0.062622309 | F10: 44255 | G10: 6673.27 | H10: =G10/G9-1 -> 0.0099752397 | J10: Market Beta Weight | K10: 0.25
B11: 44286 | C11: 5.48 | D11: =C11/C10-1 -> 0.0092081031 | F11: 44286 | G11: 6790.67 | H11: =G11/G10-1 -> 0.017592575
B12: 44316 | C12: 6.81 | D12: =C12/C11-1 -> 0.24270073 | F12: 44316 | G12: 7025.82 | H12: =G12/G11-1 -> 0.034628395 | J12: Adj Beta | K12: =K6*K7+(K9*K10) -> 0.92940315
B13: 44347 | C13: 6.56 | D13: =C13/C12-1 -> -0.03671072 | F13: 44347 | G13: 7161.63 | H13: =G13/G12-1 -> 0.019330128
B14: 44377 | C14: 6.38 | D14: =C14/C13-1 -> -0.027439024 | F14: 44377 | G14: 7313.02 | H14: =G14/G13-1 -> 0.021139042
B15: 44408 | C15: 7.6 | D15: =C15/C14-1 -> 0.19122257 | F15: 44408 | G15: 7392.62 | H15: =G15/G14-1 -> 0.010884696
B16: 44439 | C16: 5.89 | D16: =C16/C15-1 -> -0.225 | F16: 44439 | G16: 7534.9 | H16: =G16/G15-1 -> 0.019246221
B17: 44469 | C17: 4.83 | D17: =C17/C16-1 -> -0.17996604 | F17: 44469 | G17: 7332.16 | H17: =G17/G16-1 -> -0.026906794
B18: 44500 | C18: 4.4 | D18: =C18/C17-1 -> -0.089026915 | F18: 44500 | G18: 7323.74 | H18: =G18/G17-1 -> -0.0011483656
B19: 44530 | C19: 4.49 | D19: =C19/C18-1 -> 0.020454545 | F19: 44530 | G19: 7255.97 | H19: =G19/G18-1 -> -0.0092534689
B20: 44561 | C20: 5.44 | D20: =C20/C19-1 -> 0.21158129 | F20: 44561 | G20: 7444.64 | H20: =G20/G19-1 -> 0.026002037
B21: 44592 | C21: 6.45 | D21: =C21/C20-1 -> 0.18566176 | F21: 44592 | G21: 6971.63 | H21: =G21/G20-1 -> -0.063536988
B22: 44620 | C22: 6.44 | D22: =C22/C21-1 -> -0.0015503876 | F22: 44620 | G22: 7049.12 | H22: =G22/G21-1 -> 0.011115048
B23: 44651 | C23: 7.81 | D23: =C23/C22-1 -> 0.21273292 | F23: 44651 | G23: 7499.59 | H23: =G23/G22-1 -> 0.063904431
B24: 44681 | C24: 7.32 | D24: =C24/C23-1 -> -0.062740077 | F24: 44681 | G24: 7435.01 | H24: =G24/G23-1 -> -0.0086111374
... B67: 45983 | C67: 5.18 | D67: =C67/C66-1 -> -0.064981949 | F67: 45983 | G67: 8416.5 | H67: =G67/G66-1 -> -0.052394431

Sheet Market Return
B2: Market Return
B4: S&P/ASX 200 Index
B6: Date | C6: Returns | D6: % Change | F6: Average R | G6: =AVERAGE(D8:D32) -> 0.050027391
B7: 36860 | C7: 3274.68 | F7: Dividend Yield | G7: 0.0327
B8: 37225 | C8: 3337.45 | D8: =C8/C7-1 -> 0.019168285 | F8: Total Average R | G8: =SUM(G6:G7) -> 0.082727391
B9: 37590 | C9: 3061.41 | D9: =C9/C8-1 -> -0.082709853
B10: 37955 | C10: 3186.39 | D10: =C10/C9-1 -> 0.040824326
B11: 38321 | C11: 3931.32 | D11: =C11/C10-1 -> 0.23378494
B12: 38686 | C12: 4634.81 | D12: =C12/C11-1 -> 0.17894499
B13: 39051 | C13: 5482.06 | D13: =C13/C12-1 -> 0.18280145
B14: 39416 | C14: 6533.15 | D14: =C14/C13-1 -> 0.19173267
B15: 39782 | C15: 3742.52 | D15: =C15/C14-1 -> -0.42714923
B16: 40147 | C16: 4701.35 | D16: =C16/C15-1 -> 0.25619903
B17: 40512 | C17: 4584.43 | D17: =C17/C16-1 -> -0.024869452
B18: 40877 | C18: 4119.82 | D18: =C18/C17-1 -> -0.10134521
B19: 41243 | C19: 4506.04 | D19: =C19/C18-1 -> 0.093746814
B20: 41608 | C20: 5320.05 | D20: =C20/C19-1 -> 0.18064864
... B32: 45983 | C32: 8416.5 | D32: =C32/C31-1 -> -0.0023387224

Sheet Growth
B2: Growth
B4: CAD (Thousands) | D4: 2019 | E4: =D4+1 -> 2020 | F4: =E4+1 -> 2021 | G4: =F4+1 -> 2022 | H4: =G4+1 -> 2023 | I4: =H4+1 -> 2024 | J4: =I4+1 -> 2025
B6: =Historicals!B24 -> Short-term Investments | D6: =Historicals!D24 -> 17907 | E6: =Historicals!E24 -> 17291 | F6: =Historicals!F24 -> 27200 | G6: =Historicals!G24 -> 30777 | H6: =Historicals!H24 -> 312 | I6: =Historicals!I24 -> 0 | J6: =Historicals!J24 -> 0
B7: =Historicals!B25 -> Receivables | D7: =Historicals!D25 -> 93012 | E7: =Historicals!E25 -> 31249 | F7: =Historicals!F25 -> 98755 | G7: =Historicals!G25 -> 124137 | H7: =Historicals!H25 -> 162268 | I7: =Historicals!I25 -> 120079 | J7: =Historicals!J25 -> 202470
B8: =Historicals!B26 -> Inventories | D8: =Historicals!D26 -> 44154 | E8: =Historicals!E26 -> 58611 | F8: =Historicals!F26 -> 66814 | G8: =Historicals!G26 -> 98861 | H8: =Historicals!H26 -> 167670 | I8: =Historicals!I26 -> 332611 | J8: =Historicals!J26 -> 357489
B9: =Historicals!B27 -> Other Current Assets | D9: =Historicals!D27 -> 24186 | E9: =Historicals!E27 -> 13035 | F9: =Historicals!F27 -> 5454 | G9: =Historicals!G27 -> 20272 | H9: =Historicals!H27 -> 80963 | I9: =Historicals!I27 -> 47368 | J9: =Historicals!J27 -> 54895
B10: Current Assets | D10: =SUM(D6:D9) -> 179259 | E10: =SUM(E6:E9) -> 120186 | F10: =SUM(F6:F9) -> 198223 | G10: =SUM(G6:G9) -> 274047 | H10: =SUM(H6:H9) -> 411213 | I10: =SUM(I6:I9) -> 500058 | J10: =SUM(J6:J9) -> 614854
B12: =Historicals!B40 -> Accounts Payable - Other | D12: =Historicals!D40 -> 44697 | E12: =Historicals!E40 -> 55158 | F12: =Historicals!F40 -> 102225 | G12: =Historicals!G40 -> 192151 | H12: =Historicals!H40 -> 178578 | I12: =Historicals!I40 -> 251778 | J12: =Historicals!J40 -> 289660
B13: =Historicals!B41 -> Current Portion of Long-term Debt | D13: =Historicals!D41 -> 35852 | E13: =Historicals!E41 -> 0 | F13: =Historicals!F41 -> 0 | G13: =Historicals!G41 -> 71995 | H13: =Historicals!H41 -> 27080 | I13: =Historicals!I41 -> 31061 | J13: =Historicals!J41 -> 40725
B14: =Historicals!B42 -> Income and Mining Taxes Payable | D14: =Historicals!D42 -> 34059 | E14: =Historicals!E42 -> 57761 | F14: =Historicals!F42 -> 191542 | G14: =Historicals!G42 -> 22744 | H14: =Historicals!H42 -> 0 | I14: =Historicals!I42 -> 40232 | J14: =Historicals!J42 -> 25895
B15: =Historicals!B43 -> Current Portion of Provisions | D15: =Historicals!D43 -> 0 | E15: =Historicals!E43 -> 0 | F15: =Historicals!F43 -> 0 | G15: =Historicals!G43 -> 0 | H15: =Historicals!H43 -> 0 | I15: =Historicals!I43 -> 0 | J15: =Historicals!J43 -> 2402
B16: Current Liabilities | D16: =SUM(D12:D15) -> 114608 | E16: =SUM(E12:E15) -> 112919 | F16: =SUM(F12:F15) -> 293767 | G16: =SUM(G12:G15) -> 286890 | H16: =SUM(H12:H15) -> 205658 | I16: =SUM(I12:I15) -> 323071 | J16: =SUM(J12:J15) -> 358682
B18: Net Working Capital | D18: =D10-D16 -> 64651 | E18: =E10-E16 -> 7267 | F18: =F10-F16 -> -95544 | G18: =G10-G16 -> -12843 | H18: =H10-H16 -> 205555 | I18: =I10-I16 -> 176987 | J18: =J10-J16 -> 256172
B20: =Historicals!B30 -> Exploration and Evaluation Assets | D20: =Historicals!D30 -> 81508 | E20: =Historicals!E30 -> 75525 | F20: =Historicals!F30 -> 76106 | G20: =Historicals!G30 -> 107810 | H20: =Historicals!H30 -> 117127 | I20: =Historicals!I30 -> 131827 | J20: =Historicals!J30 -> 148029
B21: =Historicals!B31 -> Property, Plant and Equipment | D21: =Historicals!D31 -> 224123 | E21: =Historicals!E31 -> 365470 | F21: =Historicals!F31 -> 504985 | G21: =Historicals!G31 -> 1070030 | H21: =Historicals!H31 -> 1261968 | I21: =Historicals!I31 -> 1545961 | J21: =Historicals!J31 -> 2046406
B22: =Historicals!B32 -> Investments | D22: =Historicals!D32 -> 2653 | E22: =Historicals!E32 -> 1546 | F22: =Historicals!F32 -> 9704 | G22: =Historicals!G32 -> 14158 | H22: =Historicals!H32 -> 14751 | I22: =Historicals!I32 -> 14509 | J22: =Historicals!J32 -> 15393
B23: =Historicals!B33 -> Intangible Assets | D23: =Historicals!D33 -> 1472 | E23: =Historicals!E33 -> 6070 | F23: =Historicals!F33 -> 6257 | G23: =Historicals!G33 -> 8545 | H23: =Historicals!H33 -> 7866 | I23: =Historicals!I33 -> 5172 | J23: =Historicals!J33 -> 5219
B24: =Historicals!B34 -> Restricted Cash | D24: =Historicals!D34 -> 0 | E24: =Historicals!E34 -> 0 | F24: =Historicals!F34 -> 44012 | G24: =Historicals!G34 -> 43736 | H24: =Historicals!H34 -> 0 | I24: =Historicals!I34 -> 0 | J24: =Historicals!J34 -> 0
B25: =Historicals!B35 -> Other Non-current Assets | D25: =Historicals!D35 -> 10800 | E25: =Historicals!E35 -> 0 | F25: =Historicals!F35 -> 0 | G25: =Historicals!G35 -> 0 | H25: =Historicals!H35 -> 8595 | I25: =Historicals!I35 -> 8589 | J25: =Historicals!J35 -> 6542
B26: =Historicals!B36 -> Advance Payments | D26: =Historicals!D36 -> 38250 | E26: =Historicals!E36 -> 32438 | F26: =Historicals!F36 -> 48303 | G26: =Historicals!G36 -> 149012 | H26: =Historicals!H36 -> 166943 | I26: =Historicals!I36 -> 83374 | J26: =Historicals!J36 -> 76307
B27: Non-Current Assets | D27: =SUM(D20:D26) -> 358806 | E27: =SUM(E20:E26) -> 481049 | F27: =SUM(F20:F26) -> 689367 | G27: =SUM(G20:G26) -> 1393291 | H27: =SUM(H20:H26) -> 1577250 | I27: =SUM(I20:I26) -> 1789432 | J27: =SUM(J20:J26) -> 2297896
B29: Invested Capital | D29: =SUM(D27,D18) -> 423457 | E29: =SUM(E27,E18) -> 488316 | F29: =SUM(F27,F18) -> 593823 | G29: =SUM(G27,G18) -> 1380448 | H29: =SUM(H27,H18) -> 1782805 | I29: =SUM(I27,I18) -> 1966419 | J29: =SUM(J27,J18) -> 2554068
B30: =Historicals!B11 -> EBIT | D30: =Historicals!D11 -> 260559 | E30: =Historicals!E11 -> 326539 | F30: =Historicals!F11 -> 774063 | G30: =Historicals!G11 -> 891080 | H30: =Historicals!H11 -> 371310 | I30: =Historicals!I11 -> 429207 | J30: =Historicals!J11 -> 320511
B32: ROIC | D32: =D30/D29 -> 0.61531395 | E32: =E30/E29 -> 0.66870428 | F32: =F30/F29 -> 1.3035248 | G32: =G30/G29 -> 0.64550059 | H32: =H30/H29 -> 0.20827292 | I32: =I30/I29 -> 0.21826833 | J32: =J30/J29 -> 0.12549039
B34: Net Capex | D34: =-SUM(Historicals!D86,Historicals!D88,Historicals!D87,Historicals!D91) -> 72314 | E34: =-SUM(Historicals!E86,Historicals!E88,Historicals!E87,Historicals!E91) -> 147995 | F34: =-SUM(Historicals!F86,Historicals!F88,Historicals!F87,Historicals!F91) -> 173152 | G34: =-SUM(Historicals!G86,Historicals!G88,Historicals!G87,Historicals!G91) -> 533443 | H34: =-SUM(Historicals!H86,Historicals!H88,Historicals!H87,Historicals!H91) -> 292209 | I34: =-SUM(Historicals!I86,Historicals!I88,Historicals!I87,Historicals!I91) -> 340156 | J34: =-SUM(Historicals!J86,Historicals!J88,Historicals!J87,Historicals!J91) -> 603990
B35: Change in WC | E35: =E18-D18 -> -57384 | F35: =F18-E18 -> -102811 | G35: =G18-F18 -> 82701 | H35: =H18-G18 -> 218398 | I35: =I18-H18 -> -28568 | J35: =J18-I18 -> 79185
B37: =B30 -> EBIT | D37: =D30 -> 260559 | E37: =E30 -> 326539 | F37: =F30 -> 774063 | G37: =G30 -> 891080 | H37: =H30 -> 371310 | I37: =I30 -> 429207 | J37: =J30 -> 320511
B38: Marginal Tax Rate | D38: 0.4 | E38: =$D$38 -> 0.4 | F38: =$D$38 -> 0.4 | G38: =$D$38 -> 0.4 | H38: =$D$38 -> 0.4 | I38: =$D$38 -> 0.4 | J38: =$D$38 -> 0.4
B39: EBIT (After Tax) | D39: =D37*(1-D38) -> 156335.4 | E39: =E37*(1-E38) -> 195923.4 | F39: =F37*(1-F38) -> 464437.8 | G39: =G37*(1-G38) -> 534648 | H39: =H37*(1-H38) -> 222786 | I39: =I37*(1-I38) -> 257524.2 | J39: =J37*(1-J38) -> 192306.6
B41: Reinvestment | E41: =SUM(E34:E35) -> 90611 | F41: =SUM(F34:F35) -> 70341 | G41: =SUM(G34:G35) -> 616144 | H41: =SUM(H34:H35) -> 510607 | I41: =SUM(I34:I35) -> 311588 | J41: =SUM(J34:J35) -> 683175
B42: Reinvestment Rate | E42: =E41/E39 -> 0.46248177 | F42: =F41/F39 -> 0.15145408 | G42: =G41/G39 -> 1.1524293 | H42: =H41/H39 -> 2.2919169 | I42: =I41/I39 -> 1.2099368 | J42: =J41/J39 -> 3.5525302
B43: Average | J43: =AVERAGE(E42:J42) -> 1.4701248
B44: Median | J44: =MEDIAN(E42:J42) -> 1.181183
B46: Growth Rate | E46: =E42*E32 -> 0.30926354 | F46: =F42*F32 -> 0.19742415 | G46: =G42*G32 -> 0.74389377 | H46: =H42*H32 -> 0.47734422 | I46: =I42*I32 -> 0.26409088 | J46: =J42*J32 -> 0.44580841
B47: Average | J47: =AVERAGE(E46:J46) -> 0.40630416
B48: Median | J48: =MEDIAN(E46:J46) -> 0.37753597

Sheet PPE Schedule
B2: PPE
B4: CAD (Thousands) | D4: 2019 | E4: =D4+1 -> 2020 | F4: =E4+1 -> 2021 | G4: =F4+1 -> 2022 | H4: =G4+1 -> 2023 | I4: =H4+1 -> 2024 | J4: =I4+1 -> 2025 | K4: =J4+1 -> 2026 | L4: =K4+1 -> 2027 | ... O4: =N4+1 -> 2030
B5: Opening Balance | E5: =D8 -> 224123 | F5: =E8 -> 365470 | G5: =F8 -> 504985 | H5: =G8 -> 1070030 | I5: =H8 -> 1261968 | J5: =I8 -> 1545961 | K5: =J8 -> 2046406 | L5: =K8 -> 2375148.8 | ... O5: =N8 -> 3141285
B6: Gross Capex | E6: =E8-E5-E7 -> 167436 | F6: =F8-F5-F7 -> 174791 | G6: =G8-G5-G7 -> 620440 | H6: =H8-H5-H7 -> 272128 | I6: =I8-I5-I7 -> 388793 | J6: =J8-J5-J7 -> 611979 | K6: =K12*'Final Income Statement'!K6 -> 502829.16 | L6: =L12*'Final Income Statement'!L6 -> 504554.41 | M6: =M12*'Final Income Statement'!M6 -> 499928.18 | N6: =N12*'Final Income Statement'!N6 -> 488950.46 | O6: =O12*'Final Income Statement'!O6 -> 471621.26
B7: Depreciation | E7: -26089 | F7: -35276 | G7: -55395 | H7: -80190 | I7: -104800 | J7: -111534 | K7: =-K27 -> -174086.39 | L7: =-L27 -> -208542.23 | M7: =-M27 -> -242682.16 | N7: =-N27 -> -276072.41 | O7: =-O27 -> -308279.27
B8: Closing Balance | D8: =Historicals!D31 -> 224123 | E8: =Historicals!E31 -> 365470 | F8: =Historicals!F31 -> 504985 | G8: =Historicals!G31 -> 1070030 | H8: =Historicals!H31 -> 1261968 | I8: =Historicals!I31 -> 1545961 | J8: =Historicals!J31 -> 2046406 | K8: =SUM(K5:K7) -> 2375148.8 | L8: =SUM(L5:L7) -> 2671160.9 | M8: =SUM(M5:M7) -> 2928407 | N8: =SUM(N5:N7) -> 3141285 | O8: =SUM(O5:O7) -> 3304627
B11: Capex as % of Beg PPE | E11: =E6/E5 -> 0.74707192 | F11: =F6/F5 -> 0.47826361 | G11: =G6/G5 -> 1.2286306 | H11: =H6/H5 -> 0.2543181 | I11: =I6/I5 -> 0.30808467 | J11: =J6/J5 -> 0.39585669 | K11: =K6/K5 -> 0.24571329 | L11: =L6/L5 -> 0.21243065 | ... O11: =O6/O5 -> 0.15013641
B12: Capex as a % of Rev | E12: =E6/Historicals!E5 -> 0.2132709 | F12: =F6/Historicals!F5 -> 0.13636211 | G12: =G6/Historicals!G5 -> 0.42472443 | H12: =H6/Historicals!H5 -> 0.19506153 | I12: =I6/Historicals!I5 -> 0.25506431 | J12: =J6/Historicals!J5 -> 0.38092058 | K12: =AVERAGE(E12:J12) -> 0.26756731 | L12: =K12-$P$12 -> 0.24756731 | M12: =L12-$P$12 -> 0.22756731 | N12: =M12-$P$12 -> 0.20756731 | O12: =N12-$P$12 -> 0.18756731 | P12: 0.02 | Q12: Step
B16: Depreciation Schedule
B18: Useful Life | C18: =F42 -> 14.643507
B20: CAD (Thousands) | J20: 2025 | K20: =J20+1 -> 2026 | L20: =K20+1 -> 2027 | M20: =L20+1 -> 2028 | N20: =M20+1 -> 2029 | O20: =N20+1 -> 2030
K21: =$K$5/$C$18 -> 139748.36 | L21: =$K$5/$C$18 -> 139748.36 | M21: =$K$5/$C$18 -> 139748.36 | N21: =$K$5/$C$18 -> 139748.36 | O21: =$K$5/$C$18 -> 139748.36
K22: =$K$6/$C$18 -> 34338.029 | L22: =$K$6/$C$18 -> 34338.029 | M22: =$K$6/$C$18 -> 34338.029 | N22: =$K$6/$C$18 -> 34338.029 | O22: =$K$6/$C$18 -> 34338.029
L23: =$L$6/$C$18 -> 34455.846 | M23: =$L$6/$C$18 -> 34455.846 | N23: =$L$6/$C$18 -> 34455.846 | O23: =$L$6/$C$18 -> 34455.846
M24: =$M$6/$C$18 -> 34139.922 | N24: =$M$6/$C$18 -> 34139.922 | O24: =$M$6/$C$18 -> 34139.922
N25: =$N$6/$C$18 -> 33390.258 | O25: =$N$6/$C$18 -> 33390.258
O26: =$O$6/$C$18 -> 32206.853
B27: Total | K27: =SUM(K21:K26) -> 174086.39 | L27: =SUM(L21:L26) -> 208542.23 | M27: =SUM(M21:M26) -> 242682.16 | N27: =SUM(N21:N26) -> 276072.41 | O27: =SUM(O21:O26) -> 308279.27
B31: Asset Category for PPE | C31: Useful Life | D31: Dep Amt | E31: Weights | F31: Useful Life * Weights
B32: Mining and Processing Equipment | C32: 15 | D32: 92532 | E32: =D32/$D$42 -> 0.59750491 | F32: =E32*C32 -> 8.9625736
B33: Locomotives, Railcars and Rails | C33: 18 | D33: 3933 | E33: =D33/$D$42 -> 0.025396477 | F33: =E33*C33 -> 0.45713658
B34: Tailings Dikes | C34: 20 | D34: 15949 | E34: =D34/$D$42 -> 0.10298714 | F34: =E34*C34 -> 2.0597427
B35: Assets under Construction | C35: 25 | D35: 0 | E35: =D35/$D$42 -> 0 | F35: =E35*C35 -> 0
B36: Mining Development and Stripping Assets | C36: 12 | D36: 20244 | E36: =D36/$D$42 -> 0.13072115 | F36: =E36*C36 -> 1.5686538
B37: Asset Rehab Obligation and Other | C37: 8 | D37: 7410 | E37: =D37/$D$42 -> 0.047848435 | F37: =E37*C37 -> 0.38278748
B38: Right-of-Use Assets - Building | C38: 15 | D38: 646 | E38: =D38/$D$42 -> 0.004171402 | F38: =E38*C38 -> 0.06257103
B39: Right-of-Use Assets - Transshipment Infra | C39: 10 | D39: 5255 | E39: =D39/$D$42 -> 0.033932999 | F39: =E39*C39 -> 0.33932999
B40: Right-of-Use Assets - Mining and Processing Equipment | C40: 20 | D40: 5405 | E40: =D40/$D$42 -> 0.034901591 | F40: =E40*C40 -> 0.69803182
B41: Right-of-Use Assets - Locomotives, Railcars and Rails | C41: 5 | D41: 3490 | E41: =D41/$D$42 -> 0.022535902 | F41: =E41*C41 -> 0.11267951
B42: Total | D42: =SUM(D32:D41) -> 154864 | E42: =SUM(E32:E41) -> 1 | F42: =SUM(F32:F41) -> 14.643507

Sheet Intangible
B2: Intangible Assets
B4: CAD (Thousands) | D4: 2019 | E4: =D4+1 -> 2020 | F4: =E4+1 -> 2021 | G4: =F4+1 -> 2022 | H4: =G4+1 -> 2023 | I4: =H4+1 -> 2024 | J4: =I4+1 -> 2025 | K4: =J4+1 -> 2026 | L4: =K4+1 -> 2027 | ... O4: =N4+1 -> 2030
B5: Opening Balance | E5: =D8 -> 1472 | F5: =E8 -> 6070 | G5: =F8 -> 6257 | H5: =G8 -> 8545 | I5: =H8 -> 7866 | J5: =I8 -> 5172 | K5: =J8 -> 5219 | L5: =K8 -> 6245.6714 | ... O5: =N8 -> 6572.0748
B6: Gross Capex | E6: =E8-E5-E7 -> 3683 | F6: =F8-F5-F7 -> -1331 | G6: =G8-G5-G7 -> 4870 | H6: =H8-H5-H7 -> 2455 | I6: =I8-I5-I7-5673 -> -5243 | J6: =J8-J5-J7 -> 1568 | K6: ='Final Income Statement'!K6*K12 -> 2570.5794 | L6: ='Final Income Statement'!L6*L12 -> 2388.4442 | M6: ='Final Income Statement'!M6*M12 -> 2789.7548 | N6: ='Final Income Statement'!N6*N12 -> 2876.0079 | O6: ='Final Income Statement'!O6*O12 -> 3008.2888
B7: Depreciation | E7: 915 | F7: 1518 | G7: -2582 | H7: -3134 | I7: -3124 | J7: -1521 | K7: =-K28 -> -1543.908 | L7: =-L28 -> -2017.3018 | M7: =-M28 -> -2570.236 | N7: =-N28 -> -3140.2657 | O7: =-O28 -> -3736.5137
B8: Closing Balance | D8: =Historicals!D33 -> 1472 | E8: =Historicals!E33 -> 6070 | F8: =Historicals!F33 -> 6257 | G8: =Historicals!G33 -> 8545 | H8: =Historicals!H33 -> 7866 | I8: =Historicals!I33 -> 5172 | J8: =Historicals!J33 -> 5219 | K8: =SUM(K5:K7) -> 6245.6714 | L8: =SUM(L5:L7) -> 6616.8138 | M8: =SUM(M5:M7) -> 6836.3326 | N8: =SUM(N5:N7) -> 6572.0748 | O8: =SUM(O5:O7) -> 5843.8499
B11: Capex as a % of Beg Intangible Asstes | E11: =E6/E5 -> 2.502038 | F11: =F6/F5 -> -0.21927512 | G11: =G6/G5 -> 0.77832827 | H11: =H6/H5 -> 0.28730252 | I11: =I6/I5 -> -0.66653954 | J11: =J6/J5 -> 0.30317092 | K11: =K6/K5 -> 0.49254253 | L11: =L6/L5 -> 0.38241592 | ... O11: =O6/O5 -> 0.45773806
B12: Capex as % of Revenue | E12: =E6/Historicals!E5 -> 0.0046912058 | F12: =F6/Historicals!F5 -> -0.0010383714 | G12: =G6/Historicals!G5 -> 0.003333776 | H12: =H6/Historicals!H5 -> 0.0017597456 | I12: =I6/Historicals!I5 -> -0.0034396252 | J12: =J6/Historicals!J5 -> 0.00097598686 | K12: =MEDIAN(E12:J12) -> 0.0013678662 | L12: =MEDIAN(F12:K12) -> 0.0011719266 | M12: =MEDIAN(G12:L12) -> 0.0012698964 | N12: =MEDIAN(H12:M12) -> 0.0012209115 | O12: =MEDIAN(I12:N12) -> 0.001196419
B17: Depreciation Schedule
B19: Useful Life | C19: =F35 -> 5.0453649
B21: CAD (Thousands) | J21: 2025 | K21: =J21+1 -> 2026 | L21: =K21+1 -> 2027 | M21: =L21+1 -> 2028 | N21: =M21+1 -> 2029 | O21: =N21+1 -> 2030
K22: =$K$5/$C$19 -> 1034.4148 | L22: =$K$5/$C$19 -> 1034.4148 | M22: =$K$5/$C$19 -> 1034.4148 | N22: =$K$5/$C$19 -> 1034.4148 | O22: =$K$5/$C$19 -> 1034.4148
K23: =$K$6/$C$19 -> 509.49327 | L23: =$K$6/$C$19 -> 509.49327 | M23: =$K$6/$C$19 -> 509.49327 | N23: =$K$6/$C$19 -> 509.49327 | O23: =$K$6/$C$19 -> 509.49327
L24: =$L$6/$C$19 -> 473.39375 | M24: =$L$6/$C$19 -> 473.39375 | N24: =$L$6/$C$19 -> 473.39375 | O24: =$L$6/$C$19 -> 473.39375
M25: =$M$6/$C$19 -> 552.93419 | N25: =$M$6/$C$19 -> 552.93419 | O25: =$M$6/$C$19 -> 552.93419
N26: =$N$6/$C$19 -> 570.02971 | O26: =$N$6/$C$19 -> 570.02971
O27: =$O$6/$C$19 -> 596.24801
B28: Total | K28: =SUM(K22:K27) -> 1543.908 | L28: =SUM(L22:L27) -> 2017.3018 | M28: =SUM(M22:M27) -> 2570.236 | N28: =SUM(N22:N27) -> 3140.2657 | O28: =SUM(O22:O27) -> 3736.5137
B32: Asset Category for PPE | C32: Useful Life | D32: Dep Amt | E32: Weights | F32: Useful Life * Weights
B33: Port Access | C33: 20 | D33: 183 | E33: =D33/D35 -> 0.12031558 | F33: =C33*E33 -> 2.4063116
B34: Software | C34: 3 | D34: 1338 | E34: =D34/D35 -> 0.87968442 | F34: =C34*E34 -> 2.6390533
B35: Total | D35: =SUM(D33:D34) -> 1521 | E35: =SUM(E33:E34) -> 1 | F35: =SUM(F33:G34) -> 5.0453649

Sheet Financing
B2: Financing
B4: Cover negative CF's with:
B5: Debt | C5: =WACC!E34 -> 0.35
B6: Equity | C6: =WACC!E35 -> 0.65
B8: Bond Yeild | C8: =AVERAGE(H13:J13) -> 0.042219668
D10: ='Final Income Statement'!D4 -> 2019 | E10: ='Final Income Statement'!E4 -> 2020 | F10: ='Final Income Statement'!F4 -> 2021 | G10: ='Final Income Statement'!G4 -> 2022 | H10: ='Final Income Statement'!H4 -> 2023 | I10: ='Final Income Statement'!I4 -> 2024 | J10: ='Final Income Statement'!J4 -> 2025 | K10: ='Final Income Statement'!K4 -> 2026 | ... O10: ='Final Income Statement'!O4 -> 2030
B11: Debt | D11: =Historicals!D41+Historicals!D46+Historicals!D47 -> 240957 | E11: =Historicals!E41+Historicals!E46+Historicals!E47 -> 275968 | F11: =Historicals!F41+Historicals!F46+Historicals!F47 -> 214951 | G11: =Historicals!G41+Historicals!G46+Historicals!G47 -> 323360 | H11: =Historicals!H41+Historicals!H46+Historicals!H47 -> 475281 | I11: =Historicals!I41+Historicals!I46+Historicals!I47 -> 539428 | J11: =Historicals!J41+Historicals!J46+Historicals!J47 -> 707301 | K11: =J11+K16 -> 703001.35 | L11: =K11+L16 -> 703001.35 | M11: =L11+M16 -> 703001.35 | N11: =M11+N16 -> 703001.35 | O11: =N11+O16 -> 703001.35
B12: Interest Expense | D12: 28943 | E12: 16920 | F12: 6624 | G12: 623 | H12: 10482 | I12: 35009 | J12: 28083 | K12: =K11*K13 -> 29680.483 | L12: =L11*L13 -> 29680.483 | M12: =M11*M13 -> 29680.483 | N12: =N11*N13 -> 29680.483 | O12: =O11*O13 -> 29680.483
B13: Interest Rate | D13: =D12/D11 -> 0.12011687 | E13: =E12/E11 -> 0.061311456 | F13: =F12/F11 -> 0.030816326 | G13: =G12/G11 -> 0.0019266452 | H13: =H12/H11 -> 0.022054322 | I13: =I12/I11 -> 0.064900228 | J13: =J12/J11 -> 0.039704454 | K13: =$C$8 -> 0.042219668 | L13: =$C$8 -> 0.042219668 | M13: =$C$8 -> 0.042219668 | N13: =$C$8 -> 0.042219668 | O13: =$C$8 -> 0.042219668
B15: FCFF | K15: =DCF!E12 -> -12284.726 | L15: =DCF!F12 -> 26517.407 | M15: =DCF!G12 -> 70242.699 | N15: =DCF!H12 -> 119446.8 | O15: =DCF!I12 -> 174826.13
B16: Debt | K16: =IF(K$15<0,K$15*$C5,0) -> -4299.6539 | L16: =IF(L$15<0,L$15*$C5,0) -> 0 | M16: =IF(M$15<0,M$15*$C5,0) -> 0 | N16: =IF(N$15<0,N$15*$C5,0) -> 0 | O16: =IF(O$15<0,O$15*$C5,0) -> 0
B17: Equity | K17: =IF(K$15<0,K$15*$C6,0) -> -7985.0716 | L17: =IF(L$15<0,L$15*$C6,0) -> 0 | M17: =IF(M$15<0,M$15*$C6,0) -> 0 | N17: =IF(N$15<0,N$15*$C6,0) -> 0 | O17: =IF(O$15<0,O$15*$C6,0) -> 0
B19: Net Interest Inc/(Exp):
B20: Int Exp On LT Debt | D20: =D12 -> 28943 | E20: =E12 -> 16920 | F20: =F12 -> 6624 | G20: =G12 -> 623 | H20: =H12 -> 10482 | I20: =I12 -> 35009 | J20: =J12 -> 28083 | K20: =K12 -> 29680.483 | ... O20: =O12 -> 29680.483
B21: Other Int Exp | D21: =D23-D20-D22 -> 21067 | E21: =E23-E20-E22 -> 67324 | F21: =F23-F20-F22 -> 15804 | G21: =G23-G20-G22 -> 12133 | H21: =H23-H20-H22 -> 21396 | I21: =I23-I20-I22 -> 15573 | J21: =J23-J20-J22 -> 39074 | K21: =-K26*'Final Income Statement'!K7 -> 30020.492 | L21: =-L26*'Final Income Statement'!L7 -> 32022.503 | M21: =-M26*'Final Income Statement'!M7 -> 33941.218 | N21: =-N26*'Final Income Statement'!N7 -> 35776.639 | O21: =-O26*'Final Income Statement'!O7 -> 37528.764
B22: Int Income | D22: 0 | E22: 0 | F22: 0 | G22: -1711 | H22: -6291 | I22: -14444 | J22: -9618 | K22: =-$K$27*'Final Income Statement'!K6 -> -9862.3935 | L22: =-$K$27*'Final Income Statement'!L6 -> -10695.71 | M22: =-$K$27*'Final Income Statement'!M6 -> -11529.027 | N22: =-$K$27*'Final Income Statement'!N6 -> -12362.344 | O22: =-$K$27*'Final Income Statement'!O6 -> -13195.661
B23: Total | D23: =-'Final Income Statement'!D13 -> 50010 | E23: =-'Final Income Statement'!E13 -> 84244 | F23: =-'Final Income Statement'!F13 -> 22428 | G23: =-'Final Income Statement'!G13 -> 11045 | H23: =-'Final Income Statement'!H13 -> 25587 | I23: =-'Final Income Statement'!I13 -> 36138 | J23: =-'Final Income Statement'!J13 -> 57539 | K23: =SUM(K20:K22) -> 49838.581 | L23: =SUM(L20:L22) -> 51007.275 | M23: =SUM(M20:M22) -> 52092.674 | N23: =SUM(N20:N22) -> 53094.778 | O23: =SUM(O20:O22) -> 54013.587
B26: Other Int Exp as a % of COS | D26: =-(D21/Historicals!D6) -> 0.059858615 | E26: =-(E21/Historicals!E6) -> 0.16857635 | F26: =-(F21/Historicals!F6) -> 0.036849297 | G26: =-(G21/Historicals!G6) -> 0.026452108 | H26: =-(H21/Historicals!H6) -> 0.02600509 | I26: =-(I21/Historicals!I6) -> 0.017616077 | J26: =-(J21/Historicals!J6) -> 0.036993381 | K26: =MEDIAN($G$26:$J$26) -> 0.026228599 | L26: =MEDIAN($G$26:$J$26) -> 0.026228599 | M26: =MEDIAN($G$26:$J$26) -> 0.026228599 | N26: =MEDIAN($G$26:$J$26) -> 0.026228599 | O26: =MEDIAN($G$26:$J$26) -> 0.026228599
B27: Int Income as a % of Rev | D27: =-(D22/Historicals!D5) -> 0 | E27: =-(E22/Historicals!E5) -> 0 | F27: =-(F22/Historicals!F5) -> 0 | G27: =-(G22/Historicals!G5) -> 0.0011712712 | H27: =-(H22/Historicals!H5) -> 0.004509393 | I27: =-(I22/Historicals!I5) -> 0.0094758623 | J27: =-(J22/Historicals!J5) -> 0.0059866337 | K27: =MEDIAN($G$27:$J$27) -> 0.0052480133 | L27: =MEDIAN($G$27:$J$27) -> 0.0052480133 | M27: =MEDIAN($G$27:$J$27) -> 0.0052480133 | N27: =MEDIAN($G$27:$J$27) -> 0.0052480133 | O27: =MEDIAN($G$27:$J$27) -> 0.0052480133

Sheet Final Income Statement
B2: Final IS
B4: CAD (Thousands) | D4: 2019 | E4: =D4+1 -> 2020 | F4: =E4+1 -> 2021 | G4: =F4+1 -> 2022 | H4: =G4+1 -> 2023 | I4: =H4+1 -> 2024 | J4: =I4+1 -> 2025 | K4: =J4+1 -> 2026 | L4: =K4+1 -> 2027 | ... O4: =N4+1 -> 2030 | R4: Year Weight | S4: Year | T4: Revenue | U4: % Growth
R5: 1 | S5: {=TRANSPOSE(D4:O4)} -> 2019 | T5: {=TRANSPOSE(D6:J6)} -> 655129
B6: Revenues | D6: =Historicals!D5 -> 655129 | E6: =Historicals!E5 -> 785086 | F6: =Historicals!F5 -> 1281815 | G6: =Historicals!G5 -> 1460806 | H6: =Historicals!H5 -> 1395088 | I6: =Historicals!I5 -> 1524294 | J6: =Historicals!J5 -> 1606579 | K6: {=TRANSPOSE(T12:T16)} -> 1879262.3 | L6: 2038049.4 | M6: 2196836.5 | N6: 2355623.6 | O6: 2514410.7 | R6: =R5+1 -> 2 | S6: 2020 | T6: 785086 | U6: =T6/T5-1 -> 0.19836857
B7: Cost of Sales | D7: =Historicals!D6 -> -351946 | E7: =Historicals!E6 -> -399368 | F7: =Historicals!F6 -> -428882 | G7: =Historicals!G6 -> -458678 | H7: =Historicals!H6 -> -822762 | I7: =Historicals!I6 -> -884022 | J7: =Historicals!J6 -> -1056243 | K7: =K8-K6 -> -1144570.9 | L7: =L8-L6 -> -1220900.2 | M7: =M8-M6 -> -1294053.8 | N7: =N8-N6 -> -1364031.6 | O7: =O8-O6 -> -1430833.7 | R7: =R6+1 -> 3 | S7: 2021 | T7: 1281815 | U7: =T7/T6-1 -> 0.63270648
B8: Gross Profit | D8: =Historicals!D7 -> 303183 | E8: =Historicals!E7 -> 385718 | F8: =Historicals!F7 -> 852933 | G8: =Historicals!G7 -> 1002128 | H8: =Historicals!H7 -> 572326 | I8: =Historicals!I7 -> 640272 | J8: =Historicals!J7 -> 550336 | K8: =K6*K33 -> 734691.38 | L8: =L6*L33 -> 817149.16 | M8: =M6*M33 -> 902782.69 | N8: =N6*N33 -> 991591.97 | O8: =O6*O33 -> 1083577 | R8: =R7+1 -> 4 | S8: 2022 | T8: 1460806 | U8: =T8/T7-1 -> 0.13963872
B9: SG&A Exp | D9: =Historicals!D8 -> -28073 | E9: =Historicals!E8 -> -37178 | F9: =Historicals!F8 -> -43693 | G9: =Historicals!G8 -> -67119 | H9: =Historicals!H8 -> -79972 | I9: =Historicals!I8 -> -87481 | J9: =Historicals!J8 -> -81221 | K9: =K10-K8 -> -103528.8 | L9: =L10-L8 -> -122466.65 | M9: =M10-M8 -> -142992.37 | N9: =N10-N8 -> -165105.96 | O9: =O10-O8 -> -188807.43 | R9: =R8+1 -> 5 | S9: 2023 | T9: 1395088 | U9: =T9/T8-1 -> -0.044987493
B10: EBITDA | D10: =Historicals!D9 -> 275110 | E10: =Historicals!E9 -> 348540 | F10: =Historicals!F9 -> 809240 | G10: =Historicals!G9 -> 935009 | H10: =Historicals!H9 -> 492354 | I10: =Historicals!I9 -> 552791 | J10: =Historicals!J9 -> 469115 | K10: =K6*K34 -> 631162.57 | L10: =L6*L34 -> 694682.51 | M10: =M6*M34 -> 759790.32 | N10: =N6*N34 -> 826486 | O10: =O6*O34 -> 894769.55 | R10: =R9+1 -> 6 | S10: 2024 | T10: 1524294 | U10: =T10/T9-1 -> 0.092614946
B11: D&A | D11: =Historicals!D10 -> -14551 | E11: =Historicals!E10 -> -22001 | F11: =Historicals!F10 -> -35177 | G11: =Historicals!G10 -> -43929 | H11: =Historicals!H10 -> -121044 | I11: =Historicals!I10 -> -123584 | J11: =Historicals!J10 -> -148604 | K11: =Intangible!K7+'PPE Schedule'!K7 -> -175630.3 | L11: =Intangible!L7+'PPE Schedule'!L7 -> -210559.54 | M11: =Intangible!M7+'PPE Schedule'!M7 -> -245252.39 | N11: =Intangible!N7+'PPE Schedule'!N7 -> -279212.68 | O11: =Intangible!O7+'PPE Schedule'!O7 -> -312015.78 | R11: =R10+1 -> 7 | S11: 2025 | T11: 1606579 | U11: =T11/T10-1 -> 0.053982368
B12: EBIT | D12: =Historicals!D11 -> 260559 | E12: =Historicals!E11 -> 326539 | F12: =Historicals!F11 -> 774063 | G12: =Historicals!G11 -> 891080 | H12: =Historicals!H11 -> 371310 | I12: =Historicals!I11 -> 429207 | J12: =Historicals!J11 -> 320511 | K12: =SUM(K10:K11) -> 455532.28 | L12: =SUM(L10:L11) -> 484122.98 | M12: =SUM(M10:M11) -> 514537.93 | N12: =SUM(N10:N11) -> 547273.32 | O12: =SUM(O10:O11) -> 582753.77 | R12: =R11+1 -> 8 | S12: 2026 | T12: =FORECAST(R12,$T$5:$T$11,$R$5:$R$11) -> 1879262.3 | U12: =T12/T11-1 -> 0.16972915
B13: Interest Inc/(Exp) | D13: =Historicals!D12 -> -50010 | E13: =Historicals!E12 -> -84244 | F13: =Historicals!F12 -> -22428 | G13: =Historicals!G12 -> -11045 | H13: =Historicals!H12 -> -25587 | I13: =Historicals!I12 -> -36138 | J13: =Historicals!J12 -> -57539 | K13: =-Financing!K23 -> -49838.581 | L13: =-Financing!L23 -> -51007.275 | M13: =-Financing!M23 -> -52092.674 | N13: =-Financing!N23 -> -53094.778 | O13: =-Financing!O23 -> -54013.587 | R13: =R12+1 -> 9 | S13: 2027 | T13: =FORECAST(R13,$T$5:$T$11,$R$5:$R$11) -> 2038049.4 | U13: =T13/T12-1 -> 0.084494383
B14: Non-Operating Inc/(Exp) | D14: =Historicals!D13 -> 0 | E14: =Historicals!E13 -> -1107 | F14: =Historicals!F13 -> 10237 | G14: =Historicals!G13 -> 8560 | H14: =Historicals!H13 -> 822 | I14: =Historicals!I13 -> -242 | J14: =Historicals!J13 -> 2175 | K14: 0 | L14: =K14 -> 0 | M14: =L14 -> 0 | N14: =M14 -> 0 | O14: =N14 -> 0 | R14: =R13+1 -> 10 | S14: 2028 | T14: =FORECAST(R14,$T$5:$T$11,$R$5:$R$11) -> 2196836.5 | U14: =T14/T13-1 -> 0.077911314
B15: Unsual Items Inc/(Exp) | D15: =Historicals!D14 -> 3062 | E15: =Historicals!E14 -> 0 | F15: =Historicals!F14 -> 0 | G15: =Historicals!G14 -> -17752 | H15: =Historicals!H14 -> 0 | I15: =Historicals!I14 -> 0 | J15: =Historicals!J14 -> 0 | K15: 0 | L15: =K15 -> 0 | M15: =L15 -> 0 | N15: =M15 -> 0 | O15: =N15 -> 0 | R15: =R14+1 -> 11 | S15: 2029 | T15: =FORECAST(R15,$T$5:$T$11,$R$5:$R$11) -> 2355623.6 | U15: =T15/T14-1 -> 0.072279893
B16: EBT | D16: =Historicals!D15 -> 213611 | E16: =Historicals!E15 -> 241188 | F16: =Historicals!F15 -> 761872 | G16: =Historicals!G15 -> 870843 | H16: =Historicals!H15 -> 346545 | I16: =Historicals!I15 -> 392827 | J16: =Historicals!J15 -> 265147 | K16: =SUM(K12:K15) -> 405693.69 | L16: =SUM(L12:L15) -> 433115.7 | M16: =SUM(M12:M15) -> 462445.25 | N16: =SUM(N12:N15) -> 494178.54 | O16: =SUM(O12:O15) -> 528740.19 | R16: =R15+1 -> 12 | S16: 2030 | T16: =FORECAST(R16,$T$5:$T$11,$R$5:$R$11) -> 2514410.7 | U16: =T16/T15-1 -> 0.067407674
B17: Tax | D17: =Historicals!D16 -> -66012 | E17: =Historicals!E16 -> -120138 | F17: =Historicals!F16 -> -297447 | G17: =Historicals!G16 -> -348258 | H17: =Historicals!H16 -> -145838 | I17: =Historicals!I16 -> -158636 | J17: =Historicals!J16 -> -123102 | K17: =-(K16*K35) -> -162277.48 | L17: =-(L16*L35) -> -173246.28 | M17: =-(M16*M35) -> -184978.1 | N17: =-(N16*N35) -> -197671.42 | O17: =-(O16*O35) -> -211496.08
B18: Net Income | D18: =Historicals!D17 -> 147599 | E18: =Historicals!E17 -> 121050 | F18: =Historicals!F17 -> 464425 | G18: =Historicals!G17 -> 522585 | H18: =Historicals!H17 -> 200707 | I18: =Historicals!I17 -> 234191 | J18: =Historicals!J17 -> 142045 | K18: =SUM(K16:K17) -> 243416.22 | L18: =SUM(L16:L17) -> 259869.42 | M18: =SUM(M16:M17) -> 277467.15 | N18: =SUM(N16:N17) -> 296507.13 | O18: =SUM(O16:O17) -> 317244.11
B20: No. of Shareholders | D20: =Historicals!D19 -> 420700 | E20: =Historicals!E19 -> 441600 | F20: =Historicals!F19 -> 478600 | G20: =Historicals!G19 -> 507600 | H20: =Historicals!H19 -> 517000 | I20: =Historicals!I19 -> 517600 | J20: =Historicals!J19 -> 518200 | K20: =J20 -> 518200 | L20: =K20 -> 518200 | M20: =L20 -> 518200 | N20: =M20 -> 518200 | O20: =N20 -> 518200
B21: EPS | D21: =Historicals!D20 -> 0.35084145 | E21: =Historicals!E20 -> 0.27411685 | F21: =Historicals!F20 -> 0.97038237 | G21: =Historicals!G20 -> 1.0295213 | H21: =Historicals!H20 -> 0.3882147 | I21: =Historicals!I20 -> 0.45245556 | J21: =Historicals!J20 -> 0.27411231 | K21: =K18/K20 -> 0.46973411 | L21: =L18/L20 -> 0.50148479 | M21: =M18/M20 -> 0.53544414 | N21: =N18/N20 -> 0.57218666 | O21: =O18/O20 -> 0.612204
B23: Growth Rates
B24: Revenue | E24: =E6/D6-1 -> 0.19836857 | F24: =F6/E6-1 -> 0.63270648 | G24: =G6/F6-1 -> 0.13963872 | H24: =H6/G6-1 -> -0.044987493 | I24: =I6/H6-1 -> 0.092614946 | J24: =J6/I6-1 -> 0.053982368 | K24: =K6/J6-1 -> 0.16972915 | L24: =L6/K6-1 -> 0.084494383 | ... O24: =O6/N6-1 -> 0.067407674
B25: =B8 -> Gross Profit | E25: =E8/D8-1 -> 0.27222832 | F25: =F8/E8-1 -> 1.2112865 | G25: =G8/F8-1 -> 0.17491995 | H25: =H8/G8-1 -> -0.42888932 | I25: =I8/H8-1 -> 0.11871905 | J25: =J8/I8-1 -> -0.1404653 | K25: =K8/J8-1 -> 0.33498694 | L25: =L8/K8-1 -> 0.11223459 | ... O25: =O8/N8-1 -> 0.092764986
B26: EBITDA | E26: =E10/D10-1 -> 0.26691142 | F26: =F10/E10-1 -> 1.3217995 | G26: =G10/F10-1 -> 0.15541619 | H26: =H10/G10-1 -> -0.47342325 | I26: =I10/H10-1 -> 0.12275111 | J26: =J10/I10-1 -> -0.15137005 | K26: =K10/J10-1 -> 0.34543251 | L26: =L10/K10-1 -> 0.10063958 | ... O26: =O10/N10-1 -> 0.082619127
B27: EBIT | E27: =E12/D12-1 -> 0.2532248 | F27: =F12/E12-1 -> 1.370507 | G27: =G12/F12-1 -> 0.15117245 | H27: =H12/G12-1 -> -0.58330341 | I27: =I12/H12-1 -> 0.15592631 | J27: =J12/I12-1 -> -0.25324843 | K27: =K12/J12-1 -> 0.42126877 | L27: =L12/K12-1 -> 0.062763279 | ... O27: =O12/N12-1 -> 0.064831319
B28: EBT | E28: =E16/D16-1 -> 0.12909916 | F28: =F16/E16-1 -> 2.1588305 | G28: =G16/F16-1 -> 0.14303059 | H28: =H16/G16-1 -> -0.60205801 | I28: =I16/H16-1 -> 0.13355264 | J28: =J16/I16-1 -> -0.32502857 | K28: =K16/J16-1 -> 0.53007085 | L28: =L16/K16-1 -> 0.067592879 | ... O28: =O16/N16-1 -> 0.069937563
B29: Net Income | E29: =E18/D18-1 -> -0.17987249 | F29: =F18/E18-1 -> 2.8366378 | G29: =G18/F18-1 -> 0.12523012 | H29: =H18/G18-1 -> -0.61593425 | I29: =I18/H18-1 -> 0.16683026 | J29: =J18/I18-1 -> -0.39346516 | K29: =K18/J18-1 -> 0.71365565 | L29: =L18/K18-1 -> 0.067592879 | ... O29: =O18/N18-1 -> 0.069937563
B32: Ratios
B33: GPM | D33: =D8/D$6 -> 0.46278367 | E33: =E8/E6 -> 0.49130668 | F33: =F8/F6 -> 0.66541038 | G33: =G8/G6 -> 0.68601033 | H33: =H8/H6 -> 0.41024365 | I33: =I8/I6 -> 0.42004495 | J33: =J8/J6 -> 0.34255147 | K33: =AVERAGE(H33:J33) -> 0.39094669 | L33: =K33+$P$33 -> 0.40094669 | M33: =L33+$P$33 -> 0.41094669 | N33: =M33+$P$33 -> 0.42094669 | O33: =N33+$P$33 -> 0.43094669 | P33: 0.01 | Q33: Step
B34: EBITDAM | D34: =D10/D$6 -> 0.41993256 | E34: =E10/E$6 -> 0.44395136 | F34: =F10/F$6 -> 0.63132355 | G34: =G10/G$6 -> 0.64006377 | H34: =H10/H$6 -> 0.35291967 | I34: =I10/I$6 -> 0.36265379 | J34: =J10/J$6 -> 0.29199622 | K34: =AVERAGE(H34:J34) -> 0.33585656 | L34: =K34+$P34 -> 0.34085656 | M34: =L34+$P34 -> 0.34585656 | N34: =M34+$P34 -> 0.35085656 | O34: =N34+$P34 -> 0.35585656 | P34: 0.005 | Q34: Step
B35: Tax Rate | D35: =-D17/D16 -> 0.30902903 | E35: =-E17/E16 -> 0.49810936 | F35: =-F17/F16 -> 0.39041598 | G35: =-G17/G16 -> 0.39990905 | H35: =-H17/H16 -> 0.42083424 | I35: =-I17/I16 -> 0.40383171 | J35: =-J17/J16 -> 0.46427831 | K35: 0.4 | L35: =K35 -> 0.4 | M35: =L35 -> 0.4 | N35: =M35 -> 0.4 | O35: =N35 -> 0.4
A38: * | B38: Notes:
B39: 1) DRPF project (commissioned Dec 2025) drives revenue growth in FY2026E-2027E through premium pricing, then stabilizes; linear regression confirms this pattern and growth rates are applied through forecast period.
B40: 2) Annual Report makes no mention of additional debt or equity issuance planned; therefore, current capital structure (as of FY2025A) is used for WACC calculation through forecast period.
B41: 3) IF function used to model revolver draw in FY2026E to cover negative free cash flow; revolver automatically repaid when cash flow turns positive in FY2027E onwards.

Sheet DCF
B2: DCF
B4: CAD (Thousands) | D4: 2025 | E4: =D4+1 -> 2026 | F4: =E4+1 -> 2027 | G4: =F4+1 -> 2028 | H4: =G4+1 -> 2029 | I4: =H4+1 -> 2030
B6: EBIT | D6: ='Final Income Statement'!J12 -> 320511 | E6: ='Final Income Statement'!K12 -> 455532.28 | F6: ='Final Income Statement'!L12 -> 484122.98 | G6: ='Final Income Statement'!M12 -> 514537.93 | H6: ='Final Income Statement'!N12 -> 547273.32 | I6: ='Final Income Statement'!O12 -> 582753.77
B7: Marginal Tax Rate | D7: =Growth!J38 -> 0.4 | E7: =D7 -> 0.4 | F7: =E7 -> 0.4 | G7: =F7 -> 0.4 | H7: =G7 -> 0.4 | I7: =H7 -> 0.4
B8: EBIT (After Tax) | D8: =Growth!J39 -> 192306.6 | E8: =E6*(1-E7) -> 273319.37 | F8: =F6*(1-F7) -> 290473.79 | G8: =G6*(1-G7) -> 308722.76 | H8: =H6*(1-H7) -> 328363.99 | I8: =I6*(1-I7) -> 349652.26
B10: Reinvestment Rate | D10: =Growth!J44 -> 1.181183 | E10: =D10+(($I10-$D10)/5) -> 1.0449464 | F10: =E10+(($I10-$D10)/5) -> 0.90870981 | G10: =F10+(($I10-$D10)/5) -> 0.77247321 | H10: =G10+(($I10-$D10)/5) -> 0.6362366 | I10: 0.5
B12: FCFF | D12: =D8*(1-D10) -> -34842.69 | E12: =E8*(1-E10) -> -12284.726 | F12: =F8*(1-F10) -> 26517.407 | G12: =G8*(1-G10) -> 70242.699 | H12: =H8*(1-H10) -> 119446.8 | I12: =I8*(1-I10) -> 174826.13
B14: Mid Year Convention | E14: 0.5 | F14: =E14+1 -> 1.5 | G14: =F14+1 -> 2.5 | H14: =G14+1 -> 3.5 | I14: =H14+1 -> 4.5
B15: Discounting Factor | E15: =1/(1+$C34)^E14 -> 0.97198461 | F15: =1/(1+$C34)^F14 -> 0.91828643 | G15: =1/(1+$C34)^G14 -> 0.86755486 | H15: =1/(1+$C34)^H14 -> 0.819626 | I15: =1/(1+$C34)^I14 -> 0.77434501
B17: PV of FCFF | E17: =E15*E12 -> -11940.564 | F17: =F15*F12 -> 24350.575 | G17: =G15*G12 -> 60939.395 | H17: =H15*H12 -> 97901.704 | I17: =I15*I12 -> 135375.74
B19: Terminal Value | I19: =I6*(1+C33)/(C34-C33) -> 15448619
B20: PV of Terminal Value | I20: =I19*I15 -> 11962561
B22: Enterprise Value | D22: =SUM(E17:I17,I20) -> 12269188
B23: Add:Cash | D23: =Historicals!J23 -> 117451
B24: Less:Debt | D24: =-WACC!C34 -> -707301
B25: Value of Equity | D25: =SUM(D22:D24) -> 11679338
B26: No. of Shareholders | D26: =Historicals!J19 -> 518200
B27: Intrinsic Price | D27: =D25/D26 -> 22.538283
B29: Current Price | D29: 5.18
B30: Premium/Discount | D30: =D27/D29 -> 4.3510198
B32: Expected Growth | C32: =Growth!J48 -> 0.37753597
B33: Terminal Growth | C33: 0.02
B34: WACC | C34: =WACC!J46 -> 0.058476503
